Workbook

Sheet Общая корреляции
B1: Тип ОГ | C1: Зонд | E1: Сорбция | G1: M, г/моль | H1: ε | I1: Kamlet–Taft | L1: DN, kcal/mol | M1: полярность | N1: μ, Д | O1: PA, E кДж/моль | P1: Размер, А
E2: г/г | F2: ммоль/г | I2: α (донор) | J2: β (акцептор) | K2: π* (поляризуемость)
A3: 1 | B3: GOrus1 | C3: 1,4-диоксан | D3: 1,4-Dioxane | E3: 0.47504621 | F3: =1000*E3/G3 -> 5.391513 | G3: 88.11 | H3: 2.2 | I3: 0 | J3: 0.373 | K3: 0.55 | L3: 14.8
A4: 2 | C4: Ac2O | D4: Acetic anhydride | E4: 0.24227642 | F4: =1000*E4/G4 -> 2.3731651 | G4: 102.09 | H4: 21 | I4: 0 | J4: 0.291 | K4: 0.71 | L4: 17 | N4: 2.8 | O4: 783.7
A5: 3 | C5: AcOH | D5: Acetic acid | E5: 0.21335807 | F5: =1000*E5/G5 -> 3.5528887 | G5: 60.052 | H5: 6.2 | I5: 1.121 | J5: 0.451 | K5: 0.58 | L5: 18.8 | N5: 1.7 | O5: 863.6
A6: 4 | C6: SOCl2 | D6: Thionyl chloride | E6: 0.076635514 | F6: =1000*E6/G6 -> 0.64415831 | G6: 118.97 | H6: 9.25 | I6: 0 | J6: 0 | K6: 0 | L6: -
A7: 5 | C7: Ацетилацетон | D7: Acetylacetone | E7: 0.0058139535 | F7: =1000*E7/G7 -> 0.058071591 | G7: 100.117 | H7: 23.1 | I7: 0.11 | J7: 0.58 | K7: 0.75 | L7: 12.7
A8: 6 | C8: ТБФ | D8: Tri-n-butyl phosphate (TBP) | E8: 0.024299065 | F8: =1000*E8/G8 -> 0.091240107 | G8: 266.32 | H8: 3.09 | I8: 0 | J8: 0.75 | K8: 0.69 | L8: 20 | N8: 0.78
A9: 7 | C9: Фурфурол | D9: Furfural | E9: 0.14143426 | F9: =1000*E9/G9 -> 1.4719764 | G9: 96.0846 | H9: 42 | I9: 0.58 | J9: 0.6 | K9: 0.75 | L9: 17.1 | N9: 3.54
A10: 8 | C10: Цитраконовый ангидрид | D10: Citraconic anhydride | E10: 0.060952381 | F10: =1000*E10/G10 -> 0.54382924 | G10: 112.08 | H10: 40.3 | I10: - | J10: - | K10: - | L10: -
A11: 9 | B11: Gorus2 | C11: 1,4-диоксан | D11: 1,4-Dioxane | E11: 0.36660617 | F11: =1000*E11/G11 -> 4.1607782 | G11: 88.11 | H11: 2.2 | I11: 0 | J11: 0.373 | K11: 0.55 | L11: 14.8
A12: 10 | C12: CD3CN | D12: Acetonitrile-d3 | E12: 0.24214418 | F12: =1000*E12/G12 -> 5.4945355 | G12: 44.07 | H12: 37.5
A13: 11 | C13: CH3CN | D13: Acetonitrile | E13: 0.16007533 | F13: =1000*E13/G13 -> 3.8992359 | G13: 41.053 | H13: 21.01 | I13: 0.19 | J13: 0.4 | K13: 0.75 | N13: 3.952 | O13: 812
A14: 12 | C14: DMF (ДМФА) | D14: Dimethylformamide (DMF) | E14: 0.37950664 | F14: =1000*E14/G14 -> 5.1923196 | G14: 73.09 | H14: 37 | I14: 0 | J14: 0.69 | K14: 1.18 | L14: 26.6 | N14: 3.96 | O14: 887.5
A15: 13 | C15: DMSO | D15: Dimethyl sulfoxide (DMSO) | E15: 0.46242775 | F15: =1000*E15/G15 -> 5.9186963 | G15: 78.13 | H15: 46.68 | I15: 0 | J15: 0.69 | K15: 1 | L15: 29.8 | N15: 3.7 | O15: 884.4
A16: 14 | C16: Et3N | D16: Triethylamine (Et3N) | E16: 0.20038168 | F16: =1000*E16/G16 -> 1.9802322 | G16: 101.191 | H16: 2.42 | I16: 0 | J16: 0.7 | K16: 0.37 | L16: 61 | N16: 0.665 | O16: 981.8
A17: 15 | C17: Et3N | D17: Triethylamine (Et3N) | E17: 0.10392157 | F17: =1000*E17/G17 -> 1.0269843 | G17: 101.191 | H17: 2.42 | I17: 0 | J17: 0.7 | K17: 0.37 | L17: 61 | N17: 0.665 | O17: 981.8
A18: 16 | C18: n-Bu-NH2 | D18: n-Butylamine | E18: 0.86491557 | F18: =1000*E18/G18 -> 11.825641 | G18: 73.139 | H18: 5.4 | I18: 0.84 | J18: 0.76 | K18: 1 | L18: 16.9 | N18: 1 | O18: 921.5
A19: 17 | C19: NMP | D19: N-Methyl-2-pyrrolidone (NMP) | E19: 0.47490347 | F19: =1000*E19/G19 -> 4.790569 | G19: 99.133 | H19: 33 | I19: 0 | J19: 0.77 | K19: 0.92 | L19: 27.3 | N19: 4.1 | O19: 923.5
A20: 18 | C20: PBr3 | D20: Phosphorus tribromide | E20: 0.48235294 | F20: =1000*E20/G20 -> 1.7819385 | G20: 270.69 | H20: 3.9 | I20: - | J20: - | K20: - | L20: -
A21: 19 | C21: TEMED | D21: N,N,N',N'-Tetramethylethylenediamine (TEMED) | E21: 0.19814815 | F21: =1000*E21/G21 -> 1.7050869 | G21: 116.21 | H21: 7.4 | I21: 0.54 | J21: 0.8 | K21: 0.87 | L21: 28.8
A22: 20 | C22: Бензол | D22: Benzene | E22: 0.099264706 | F22: =1000*E22/G22 -> 1.2708322 | G22: 78.11 | H22: 2.2825 | O22: 750.4
A23: 21 | C23: бензонитрил | D23: Benzonitrile | E23: 0.12548263 | F23: =1000*E23/G23 -> 1.217805 | G23: 103.04 | H23: 25.9 | N23: 4.19 | O23: 811.5
A24: 22 | C24: вода | D24: Water | E24: 0.31021195 | F24: =1000*E24/G24 -> 17.219647 | G24: 18.015 | H24: 80.1 | N24: 1.85 | O24: 691
A25: 23 | C25: вода | D25: Water | E25: 0.48062016 | F25: =1000*E25/G25 -> 26.678887 | G25: 18.015 | H25: 80.1 | N25: 1.85 | O25: 691
A26: 24 | C26: Дейтеробензол (Бензол-D6) | D26: Benzene-d6 (Deuterated benzene) | E26: 0.11741683 | F26: =1000*E26/G26 -> 1.3953476 | G26: 84.1488 | H26: 2.28
A27: 25 | C27: дибутилфталат | D27: Dibutyl phthalate | E27: 0.15612648 | F27: =1000*E27/G27 -> 0.56089988 | G27: 278.35 | H27: 6.44 | I27: 0.07 | J27: 0.45 | K27: 1.03 | L27: - | N27: 2.82
A28: 26 | C28: Дициклогексиламин | D28: Dicyclohexylamine | E28: 0.06012024 | F28: =1000*E28/G28 -> 0.33156434 | G28: 181.323 | H28: 2.27 | I28: - | J28: - | K28: - | L28: -
A29: 27 | C29: Лимонен -D, (-R) | D29: Limonene, D (R) | E29: 0.11089494 | F29: =1000*E29/G29 -> 0.81396757 | G29: 136.24 | H29: 2.3 | I29: 0 | J29: 0 | K29: 0.54 | L29: -
A30: 28 | C30: монометиланилин | D30: N-Methylaniline | E30: 0.15589354 | F30: =1000*E30/G30 -> 1.4548279 | G30: 107.156 | H30: 6.06 | I30: 0.17 | J30: 0.47 | K30: 0.82 | L30: 11.5 | O30: 916.6
A31: 29 | C31: Морфолин | D31: Morpholine | E31: 0.6634981 | F31: =1000*E31/G31 -> 7.617659 | G31: 87.1 | H31: 7.4 | I31: 0.6 | J31: 0.66 | K31: 0.64 | L31: 27.1 | N31: 1.55 | O31: 924.3
A32: 30 | C32: пероксид водорода | D32: Hydrogen peroxide | E32: 0.13992537 | F32: =1000*E32/G32 -> 4.1136736 | G32: 34.0147 | H32: 74.6 | N32: 1.573 | O32: 674.5
A33: 31 | C33: пивалонитрил | D33: Pivalonitrile | E33: 0.10734463 | F33: =1000*E33/G33 -> 1.2912242 | G33: 83.134 | H33: 21.1 | N33: 3.95 | O33: 810.9
A34: 32 | C34: пиперидин | D34: Piperidine | E34: 0.57142857 | F34: =1000*E34/G34 -> 6.7108464 | G34: 85.15 | H34: 5.8 | I34: 0 | J34: 1.04 | K34: 0.3 | L34: 27.5 | N34: 1.19 | O34: 954
A35: 33 | C35: пиридазин | D35: Pyridazine | E35: 0.078754579 | F35: =1000*E35/G35 -> 0.98332599 | G35: 80.09 | H35: 4.22 | O35: 907.2
A36: 34 | C36: пиридин | D36: Pyridine | E36: 0.39130435 | F36: =1000*E36/G36 -> 4.9469576 | G36: 79.1 | H36: 12.4 | I36: 0.26 | J36: 0.57 | K36: 0.77 | L36: 33.1 | N36: 2.215 | O36: 930
A37: 35 | C37: пиридин | D37: Pyridine | E37: 0.55090909 | F37: =1000*E37/G37 -> 6.9646287 | G37: 79.101 | H37: 12.4 | I37: 0.26 | J37: 0.57 | K37: 0.77 | L37: 33.1 | N37: 2.215 | O37: 930
A38: 36 | C38: пиридин-д5 | D38: Pyridine-d5 | E38: 0.31568998 | F38: =1000*E38/G38 -> 3.7524068 | G38: 84.13 | H38: 12.4 | O38: 948.3
A39: 37 | C39: пирролидин | D39: Pyrrolidine | E39: 0.86055046 | F39: =1000*E39/G39 -> 12.10168 | G39: 71.11 | H39: 8.3 | I39: 0.16 | J39: 0.7 | K39: 0.39 | L39: 33 | N39: 1.57
A40: 38 | C40: ТГФ | D40: Tetrahydrofuran (THF) | E40: 0.34160305 | F40: =1000*E40/G40 -> 4.7372494 | G40: 72.11 | H40: 7.6 | I40: 0 | J40: 0.55 | K40: 1 | L40: 20 | N40: 1.75 | O40: 822.1
...

Sheet FTIR probes
B1: Топохимия | H1: Сушка цеолитов | J1: H-форма | K1: CBV FAY Y | N1: Топохимия | Z1: Rusgraphene 2 | AC1: 45720 | AD1: 45727 | AF1: Rusgraphene 2 | AI1: 45733 | AJ1: 45741 | AL1: Rusgraphene 2 | AO1: 45733 | AP1: 45741 | BD1: Rusgraphene 2 | BG1: 45841 | BH1: 45848 | BJ1: Ozon graphene | BM1: 45862 | BN1: 45869 | BP1: Rusgraphene 2 | BS1: 45887 | BT1: 45894 | BV1: Rusgraphene 2 | BY1: 45897 | BZ1: 45904 | CB1: Rusgraphene 2 | CE1: 45897 | CF1: 45904 | CH1: Rusgraphene 2 | CK1: 45897 | CL1: 45904 | CN1: SG-10 | CQ1: 45899 | CR1: 45906 | CT1: HGO-N3 | CW1: 45917 | CX1: 45924 | CZ1: Go rus2 3 um | DC1: 45917 | DD1: 45924
E2: 45680 | F2: 45687 | G2: с крышкой | K2: 45685 | L2: 45688 | Q2: 45688 | R2: 45695 | W2: 45695 | X2: 45702 | Y2: 04/03/25-11/03/25 | Z2: Морфолин | AC2: 0.45486111 | AD2: 0.45138889 | AE2: 17.03.2025-24.03.2025 | AF2: NMP | AI2: 0.68055556 | AJ2: 0.45138889 | AK2: 17.03.2025-24.03.2025 | AL2: TEMED | AO2: 0.68055556 | AP2: 0.45138889 | AR2: Rusgraphene 2 | AU2: 45831 | AV2: 45838 | AX2: Rusgraphene 2 | BA2: 45841 | BB2: 45848 | BC2: 45848 | BD2: ТГФ | BG2: 0.58333333 | BH2: 0.60416667 | BI2: 45869 | BJ2: Et3N | BM2: 0.58333333 | BN2: 0.60416667 | BO2: 45894 | BP2: тяжелая вода | BS2: 0.66666667 | BT2: 0.6875 | BU2: 45904 | BV2: тяжелая вода | BY2: 0.70833333 | BZ2: 0.6875 | CA2: 45904 | CB2: пиридин-д5 | CE2: 0.70833333 | CF2: 0.6875 | CG2: 45904 | CH2: пивалонитрил | CK2: 0.70833333 | CL2: 0.6875 | CM2: 45904 | CN2: пиридин | CQ2: 0.625 | CR2: 0.39583333 | CS2: 45917 | CT2: пиридин | CW2: 0.66666667 | CX2: 0.54166667 | CY2: 45917 | CZ2: пиридин | DC2: 0.66666667 | DD2: 0.54166667
A3: 23-30/01/25 | B3: Ac2O | E3: 0.68055556 | F3: 0.62847222 | G3: 28-31/01/25 | K3: 0.5625 | L3: 0.46180556 | M3: 31/01-07/02/25 | N3: 1,4-диоксан | Q3: 0.44791667 | R3: 0.45763889 | S3: 07/02/25-14/02/25 | T3: Фурфурол | W3: 0.64930556 | X3: 0.39930556 | Z3: 87.1 | AA3: г/моль | AB3: Время, ч | AC3: 0 | AD3: 168 | AE3: #VALUE! | AF3: 99.133 | AG3: г/моль | AH3: Время, ч | AI3: 0 | AJ3: 168 | AK3: #VALUE! | AL3: 116.21 | AM3: г/моль | AN3: Время, ч | AO3: 0 | AP3: 168 | AQ3: 45838 | AR3: PBr3 | AU3: 0.45833333 | AV3: 0.60416667 | AW3: 45848 | AX3: 1,4-диоксан | BA3: 0.58333333 | BB3: 0.60416667 | BD3: 72.11 | BE3: г/моль | BF3: Время, ч | BG3: 0 | BH3: 168 | BJ3: 101.191 | BK3: г/моль | BL3: Время, ч | BM3: 0 | BN3: 168 | BP3: 20.0276 | BQ3: г/моль | BR3: Время, ч | BS3: 0 | BT3: 168 | BV3: 20.0276 | BW3: г/моль | BX3: Время, ч | BY3: 0 | BZ3: 168 | CB3: 84.13 | CC3: г/моль | CD3: Время, ч | CE3: 0 | CF3: 168 | CH3: 83.134 | CI3: г/моль | CJ3: Время, ч | CK3: 0 | CL3: 168 | CN3: 79.101 | CO3: г/моль | CP3: Время, ч | CQ3: 0 | CR3: 168 | CT3: 79.101 | CU3: г/моль | CV3: Время, ч | CW3: 0 | CX3: 168 | CZ3: 79.101 | DA3: г/моль | DB3: Время, ч | DC3: 0 | DD3: 168
B4: 102.09 | C4: г/моль | D4: Время, ч | E4: 0 | F4: 167 | J4: Время, ч | K4: 0 | L4: 70 | N4: 88.11 | O4: г/моль | P4: Время, ч | Q4: 0 | T4: 96.0846 | U4: г/моль | V4: Время, ч | W4: 0 | X4: 162 | AB4: m тигель, г | AH4: m тигель, г | AN4: m тигель, г | AR4: 270.69 | AS4: г/моль | AT4: Время, ч | AU4: 0 | AV4: 168 | AX4: 88.11 | AY4: г/моль | AZ4: Время, ч | BA4: 0 | BB4: 168 | BF4: m тигель, г | BG4: 23.1605 | BL4: m тигель, г | BM4: 30.9725 | BR4: m тигель, г | BS4: 26.734 | BX4: m тигель, г | BY4: 30.384 | CD4: m тигель, г | CE4: 30.3913 | CJ4: m тигель, г | CK4: 32.9465 | CP4: m тигель, г | CQ4: 28.949 | CV4: m тигель, г | CW4: 30.3849 | DB4: m тигель, г | DC4: 30.86037
D5: m тигель, г | E5: 26.7337 | J5: m тигель, г | K5: 32.511 | P5: m тигель, г | Q5: 26.0495 | V5: m тигель, г | W5: 24.0239 | Y5: #VALUE! | AB5: m GO, г | AC5: 0.0526 | AH5: m GO, г | AI5: 0.0518 | AN5: m GO, г | AO5: 0.054 | AT5: m тигель, г | AU5: 31.0608 | AZ5: m тигель, г | BA5: 26.7343 | BF5: m GO, г | BG5: 0.0524 | BL5: m GO, г | BM5: 0.051 | BR5: m GO, г | BS5: 0.0573 | BX5: m GO, г | BY5: 0.0507 | CD5: m GO, г | CE5: 0.0529 | CJ5: m GO, г | CK5: 0.0531 | CP5: m GO, г | CQ5: 0.0153 | CV5: m GO, г | CW5: 0.01 | DB5: m GO, г | DC5: 0.00071
D6: m GO, г | E6: 0.0615 | J6: m цеолит, г | K6: 0.1068 | P6: m GO, г | Q6: 0.0541 | V6: m GO, г | W6: 0.0502 | AA6: расчет | AB6: m тигель+GO, г | AC6: 29.4654 | AG6: расчет | AH6: m тигель+GO, г | AI6: 43.2417 | AM6: расчет | AN6: m тигель+GO, г | AO6: 26.1043 | AT6: m GO, г | AU6: 0.051 | AZ6: m GO, г | BA6: 0.0551 | BE6: расчет | BF6: m тигель+GO, г | BG6: 23.2134 | BK6: расчет | BL6: m тигель+GO, г | BM6: 31.0239 | BQ6: расчет | BR6: m тигель+GO, г | BS6: 26.7887 | BW6: расчет | BX6: m тигель+GO, г | BY6: 30.4356 | CC6: расчет | CD6: m тигель+GO, г | CE6: 30.4441 | CI6: расчет | CJ6: m тигель+GO, г | CK6: 33.0001 | CO6: расчет | CP6: m тигель+GO, г | CQ6: 28.9652 | CU6: расчет | CV6: m тигель+GO, г | CW6: 30.3941 | DA6: расчет | DB6: m тигель+GO, г | DC6: 30.86132
C7: расчет | D7: m тигель+GO, г | E7: =E5+E6 -> 26.7952 | I7: расчет | J7: m тигель+цеолит, г | K7: =K5+K6 -> 32.6178 | O7: расчет | P7: m тигель+GO, г | Q7: =Q5+Q6 -> 26.1036 | U7: расчет | V7: m тигель+GO, г | W7: =W5+W6 -> 24.0741 | AA7: взвешено | AB7: m тигель+GO, г | AD7: 29.5003 | AG7: взвешено | AH7: m тигель+GO, г | AJ7: 43.2663 | AM7: взвешено | AN7: m тигель+GO, г | AP7: 26.115 | AS7: расчет | AT7: m тигель+GO, г | AU7: 31.1117 | AY7: расчет | AZ7: m тигель+GO, г | BA7: 26.79 | BE7: взвешено | BF7: m тигель+GO, г | BH7: 23.2313 | BK7: взвешено | BL7: m тигель+GO, г | BN7: 31.0292 | BQ7: взвешено | BR7: m тигель+GO, г | BT7: 26.8125 | BW7: взвешено | BX7: m тигель+GO, г | BZ7: 30.4575 | CC7: взвешено | CD7: m тигель+GO, г | CF7: 30.4608 | CI7: взвешено | CJ7: m тигель+GO, г | CL7: 33.0058 | CO7: взвешено | CP7: m тигель+GO, г | CR7: =28.949+0.0309 -> 28.9799 | CU7: взвешено | CV7: m тигель+GO, г | CX7: 30.4188 | DA7: взвешено | DB7: m тигель+GO, г | DD7: 30.8625
C8: взвешено | D8: m тигель+GO, г | E8: 26.7956 | F8: 26.8105 | I8: взвешено | J8: m тигель+цеолит, г | K8: 32.6179 | L8: 32.6102 | O8: взвешено | P8: m тигель+GO, г | Q8: 26.104 | R8: 26.1297 | U8: взвешено | V8: m тигель+GO, г | W8: 24.0746 | X8: 24.0817 | AB8: Δр-Δэксп, г | AH8: Δр-Δэксп, г | AN8: Δр-Δэксп, г | AS8: взвешено | AT8: m тигель+GO, г | AV8: 31.1363 | AY8: взвешено | AZ8: m тигель+GO, г | BB8: 26.8102 | BF8: Δр-Δэксп, г | BL8: Δр-Δэксп, г | BR8: Δр-Δэксп, г | BX8: Δр-Δэксп, г | CD8: Δр-Δэксп, г | CJ8: Δр-Δэксп, г | CP8: Δр-Δэксп, г | CV8: Δр-Δэксп, г | DB8: Δр-Δэксп, г
D9: Δр-Δэксп, г | E9: =E7-E8 -> -0.0004 | J9: Δр-Δэксп, г | K9: =K7-K8 -> -0.0001 | P9: Δр-Δэксп, г | Q9: =Q7-Q8 -> -0.0004 | V9: Δр-Δэксп, г | W9: =W7-W8 -> -0.0005 | AB9: прирост массы | AD9: =AD7-AC6 -> 0.0349 | AH9: прирост массы | AJ9: =AJ7-AI6 -> 0.0246 | AN9: прирост массы | AP9: =AP7-AO6 -> 0.0107 | AT9: Δр-Δэксп, г | AZ9: Δр-Δэксп, г | BF9: прирост массы | BH9: =BH7-BG6 -> 0.0179 | BL9: прирост массы | BN9: =BN7-BM6 -> 0.0053 | BR9: прирост массы | BT9: =BT7-BS6 -> 0.0238 | BX9: прирост массы | BZ9: =BZ7-BY6 -> 0.0219 | CD9: прирост массы | CF9: =CF7-CE6 -> 0.0167 | CJ9: прирост массы | CL9: =CL7-CK6 -> 0.0057 | CM9: ЖИЖА внутри! | CP9: прирост массы | CR9: =CR7-CQ6 -> 0.0147 | CV9: прирост массы | CX9: =CX7-CW6 -> 0.0247 | DB9: прирост массы | DD9: =DD7-DC6 -> 0.00118
D10: прирост массы | F10: =F8-E8 -> 0.0149 | J10: прирост массы | L10: =L8-K8 -> -0.0077 | P10: прирост массы | R10: =R8-Q8 -> 0.0257 | V10: прирост массы | X10: =X8-W8 -> 0.0071 | AB10: ω(морфолина в GO), % | AD10: =AD9/(AD9+AC5) -> 0.39885714 | AH10: ω(nmp в GO), % | AJ10: =AJ9/(AJ9+AI5) -> 0.32198953 | AN10: ω(TEMED в GO), % | AP10: =AP9/(AP9+AO5) -> 0.16537867 | AT10: прирост массы | AV10: =AV8-AU7 -> 0.0246 | AZ10: прирост массы | BB10: =BB8-BA7 -> 0.0202 | BF10: ω(probe в GO), % | BH10: =BH9/(BH9+BG5) -> 0.25462304 | BL10: ω(probe в GO), % | BN10: =BN9/(BN9+BM5) -> 0.094138544 | BR10: ω(probe в GO), % | BT10: =BT9/(BT9+BS5) -> 0.29346486 | BX10: ω(probe в GO), % | BZ10: =BZ9/(BZ9+BY5) -> 0.30165289 | CD10: ω(probe в GO), % | CF10: =CF9/(CF9+CE5) -> 0.23994253 | CJ10: ω(probe в GO), % | CL10: =CL9/(CL9+CK5) -> 0.096938776 | CP10: ω(probe в GO), % | CR10: =CR9/(CR9+CQ5) -> 0.49 | CV10: ω(probe в GO), % | CX10: =CX9/(CX9+CW5) -> 0.71181556 | DB10: ω(probe в GO), % | DD10: =DD9/(DD9+DC5) -> 0.62433862
D11: ω(Ac2O в GO), % | F11: =F10/(F10+E6) -> 0.19502618 | J11: ω(H2O в цеолите), % | L11: =L10/(L10+K6) -> -0.077699294 | P11: ω(1,4-диоксан в GO), % | R11: =R10/(R10+Q6) -> 0.32205514 | V11: ω(фурфурол в GO), % | X11: =X10/(X10+W6) -> 0.12390925 | Y11: Сорбция, ммоль/г | AB11: г/г | AC11: =AD9/AC5 -> 0.6634981 | AD11: =1000*(AD9/Z3)/AC5 -> 7.617659 | AE11: Сорбция, ммоль/г | AH11: г/г | AI11: =AJ9/AI5 -> 0.47490347 | AJ11: =1000*(AJ9/AF3)/AI5 -> 4.790569 | AK11: Сорбция, ммоль/г | AN11: г/г | AO11: =AP9/AO5 -> 0.19814815 | AP11: =1000*(AP9/AL3)/AO5 -> 1.7050869 | AT11: ω(probe в GO), % | AV11: =AV10/(AV10+AU6) -> 0.32539683 | AZ11: ω(probe в GO), % | BB11: =BB10/(BB10+BA6) -> 0.26826029 | BC11: Сорбция, ммоль/г | BF11: г/г | BG11: =BH9/BG5 -> 0.34160305 | BH11: =1000*(BH9/BD3)/BG5 -> 4.7372494 | BI11: Сорбция, ммоль/г | BL11: г/г | BM11: =BN9/BM5 -> 0.10392157 | BN11: =1000*(BN9/BJ3)/BM5 -> 1.0269843 | BO11: Сорбция, ммоль/г | BR11: г/г | BS11: =BT9/BS5 -> 0.41535777 | BT11: =1000*(BT9/BP3)/BS5 -> 20.739268 | BU11: Сорбция, ммоль/г | BX11: г/г | BY11: =BZ9/BY5 -> 0.43195266 | BZ11: =1000*(BZ9/BV3)/BY5 -> 21.567869 | CA11: Сорбция, ммоль/г | CD11: г/г | CE11: =CF9/CE5 -> 0.31568998 | CF11: =1000*(CF9/CB3)/CE5 -> 3.7524068 | CG11: Сорбция, ммоль/г | CJ11: г/г | CK11: =CL9/CK5 -> 0.10734463 | CL11: =1000*(CL9/CH3)/CK5 -> 1.2912242 | CM11: Сорбция, ммоль/г | CP11: г/г | CQ11: =CR9/CQ5 -> 0.96078431 | CR11: =1000*(CR9/CN3)/CQ5 -> 12.146298 | CS11: Сорбция, ммоль/г | CV11: г/г | CW11: =CX9/CW5 -> 2.47 | CX11: =1000*(CX9/CT3)/CW5 -> 31.225901 | CY11: Сорбция, ммоль/г | DB11: г/г | DC11: =DD9/DC5 -> 1.6619718 | DD11: =1000*(DD9/CZ3)/DC5 -> 21.010756
A12: Сорбция, ммоль/г | D12: г/г | E12: =F10/E6 -> 0.24227642 | F12: =1000*(F10/B4)/E6 -> 2.3731651 | M12: Сорбция, ммоль/г | P12: г/г | Q12: =R10/Q6 -> 0.47504621 | R12: =1000*(R10/N4)/Q6 -> 5.391513 | S12: Сорбция, ммоль/г | V12: г/г | W12: =X10/W6 -> 0.14143426 | X12: =1000*(X10/T4)/W6 -> 1.4719764 | AQ12: Сорбция, ммоль/г | AT12: г/г | AU12: =AV10/AU6 -> 0.48235294 | AV12: =1000*(AV10/AR4)/AU6 -> 1.7819385 | AW12: Сорбция, ммоль/г | AZ12: г/г | BA12: =BB10/BA6 -> 0.36660617 | BB12: =1000*(BB10/AX4)/BA6 -> 4.1607782 | BJ12: Rusgraphene 2 | BM12: 45887 | BN12: 45894 | BP12: Rusgraphene 2 | BS12: 45887 | BT12: 45894 | BV12: Rusgraphene 2 | BY12: 45897 | BZ12: 45904 | CB12: Rusgraphene 2 | CE12: 45897 | CF12: 45904 | CH12: Rusgraphene 2 | CK12: 45897 | CL12: 45904 | CN12: VVB-522 | CQ12: 45899 | CR12: 45906
Z13: Rusgraphene 2 | AC13: 45726 | AD13: 45733 | AF13: Rusgraphene 2 | AI13: 45733 | AJ13: 45741 | BC13: КАПАЕТ НА ДНЕ ЛУЖА | BI13: 45894 | BJ13: БЗЛ | BM13: 0.66666667 | BN13: 0.6875 | BO13: 45894 | BP13: пероксид водорода | BS13: 0.66666667 | BT13: 0.6875 | BU13: 45904 | BV13: вода | BY13: 0.70833333 | BZ13: 0.6875 | CA13: 45904 | CB13: пиридазин | CE13: 0.70833333 | CF13: 0.6875 | CG13: 45904 | CH13: CD3CN | CK13: 0.70833333 | CL13: 0.6875 | CM13: 45904 | CN13: пиридин | CQ13: 0.625 | CR13: 0.39583333 | CT13: BGO | CW13: 45917 | CX13: 45924
G14: без крышки | K14: 45685 | L14: 45688 | Q14: 45692 | R14: 45699 | S14: 4 сут | Y14: 10/03/25-17/03/25 | Z14: Дициклогексиламин | AC14: 0.35416667 | AE14: 17.03.2025-24.03.2025 | AF14: пирролидин | AI14: 0.68055556 | AJ14: 0.45138889 | AL14: Rusgraphene 2 | AO14: 45733 | AP14: 45741 | AR14: Rusgraphene 2 | AU14: 45831 | AV14: 45838 | AW14: ПОВТОР | BD14: Rusgraphene 2 | BG14: 45841 | BH14: 45848 | BJ14: 78.11 | BK14: г/моль | BL14: Время, ч | BM14: 0 | BN14: 168 | BP14: 34.0147 | BQ14: г/моль | BR14: Время, ч | BS14: 0 | BT14: 168 | BV14: 18.015 | BW14: г/моль | BX14: Время, ч | BY14: 0 | BZ14: 168 | CB14: 80.09 | CC14: г/моль | CD14: Время, ч | CE14: 0 | CF14: 168 | CH14: 44.07 | CI14: г/моль | CJ14: Время, ч | CK14: 0 | CL14: 168 | CN14: 79.101 | CO14: г/моль | CP14: Время, ч | CQ14: 0 | CR14: 168 | CS14: 45917 | CT14: пиридин | CW14: 0.66666667 | CX14: 0.54166667
E15: 45681 | F15: 45688 | G15: 28-31/01/25 | K15: 0.5625 | L15: 0.46180556 | M15: 04/02-11/02/25 | N15: Ацетилацетон | Q15: 0.43402778 | R15: 0.54166667 | W15: 45695 | X15: 45699 | Z15: 181.323 | AA15: г/моль | AB15: Время, ч | AC15: 0 | AE15: #VALUE! | AF15: 71.11 | AG15: г/моль | AH15: Время, ч | AI15: 0 | AJ15: 168 | AK15: 28.03.2025-04.04.2025 | AL15: пиридин | AO15: 0.68055556 | AP15: 0.64583333 | AQ15: 45838 | AR15: дибутилфталат | AU15: 0.45833333 | AV15: 0.60416667 | BC15: 45848 | BD15: Этилацетат | BG15: 0.58333333 | BH15: 0.60416667 | BL15: m тигель, г | BM15: 23.9913 | BR15: m тигель, г | BS15: 23.1601 | BX15: m тигель, г | BY15: 32.9264 | CD15: m тигель, г | CE15: 30.7647 | CJ15: m тигель, г | CK15: 30.86 | CP15: m тигель, г | CQ15: 30.742 | CT15: 79.101 | CU15: г/моль | CV15: Время, ч | CW15: 0 | CX15: 168
A16: 23-31/01/25 | B16: AcOH | E16: 0.42708333 | F16: 0.43055556 | J16: Время, ч | K16: 0 | L16: 70 | N16: 100.117 | O16: г/моль | P16: Время, ч | Q16: 0 | S16: 07/02/25-14/02/25 | T16: Цитраконовый ангидрид | W16: 0.66666667 | X16: 0.54166667 | AB16: m тигель, г | AH16: m тигель, г | AL16: 79.1 | AM16: г/моль | AN16: Время, ч | AO16: 0 | AP16: 168 | AR16: 278.35 | AS16: г/моль | AT16: Время, ч | AU16: 0 | AV16: 168 | AX16: Rusgraphene 2 | BA16: 45841 | BB16: 45848 | BD16: 88.11 | BE16: г/моль | BF16: Время, ч | BG16: 0 | BH16: 168 | BL16: m GO, г | BM16: 0.0544 | BR16: m GO, г | BS16: 0.0536 | BX16: m GO, г | BY16: 0.0516 | CD16: m GO, г | CE16: 0.0546 | CJ16: m GO, г | CK16: 0.0541 | CP16: m GO, г | CQ16: 0.012 | CV16: m тигель, г | CW16: 30.6138 | CY16: CH3CN | CZ16: H2O | DA16: m тигля | DB16: m навески | DC16: m тигля + навески | DD16: m после сорбции
B17: 60.052 | C17: г/моль | D17: Время, ч | E17: 0 | F17: 168 | J17: m тигель, г | K17: 19.3281 | P17: m тигель, г | Q17: 26.7335 | T17: 112.08 | U17: г/моль | V17: Время, ч | W17: 0 | Y17: #VALUE! | AB17: m GO, г | AC17: 0.0499 | AH17: m GO, г | AI17: 0.0545 | AN17: m тигель, г | AO17: 44.0615 | AT17: m тигель, г | AU17: 23.1596 | AW17: 45848 | AX17: DMSO | BA17: 0.58333333 | BB17: 0.60416667 | BF17: m тигель, г | BG17: 30.9169 | BK17: расчет | BL17: m тигель+GO, г | BM17: 24.0469 | BQ17: расчет | BR17: m тигель+GO, г | BS17: 23.214 | BW17: расчет | BX17: m тигель+GO, г | BY17: 32.9788 | CC17: расчет | CD17: m тигель+GO, г | CE17: 30.8197 | CI17: расчет | CJ17: m тигель+GO, г | CK17: 30.9139 | CO17: расчет | CP17: m тигель+GO, г | CQ17: 30.7547 | CV17: m GO, г | CW17: 0.0113 | CY17: 1 | CZ17: 0 | DA17: 32.9269 | DB17: 0.0529 | DC17: 32.98 | DD17: 32.9961
D18: m тигель, г | E18: 24.7668 | J18: m цеолит, г | K18: 0.5316 | P18: m GO, г | Q18: 0.0516 | V18: m тигель, г | W18: 23.6003 | AA18: расчет | AB18: m тигель+GO, г | AC18: 32.5111 | AG18: расчет | AH18: m тигель+GO, г | AI18: 23.6231 | AN18: m GO, г | AO18: 0.0069 | AT18: m GO, г | AU18: 0.0506 | AX18: 78.13 | AY18: г/моль | AZ18: Время, ч | BA18: 0 | BB18: 168 | BF18: m GO, г | BG18: 0.0597 | BK18: взвешено | BL18: m тигель+GO, г | BN18: 24.0523 | BQ18: взвешено | BR18: m тигель+GO, г | BT18: 23.2215 | BW18: взвешено | BX18: m тигель+GO, г | BZ18: 33.0036 | CC18: взвешено | CD18: m тигель+GO, г | CF18: 30.824 | CI18: взвешено | CJ18: m тигель+GO, г | CL18: 30.927 | CO18: взвешено | CP18: m тигель+GO, г | CR18: 30.7591 | CU18: расчет | CV18: m тигель+GO, г | CW18: 30.6252 | CY18: 0 | CZ18: 1 | DA18: 31.3097 | DB18: 0.0558 | DC18: 31.3658 | DD18: 31.3961
D19: m GO, г | E19: 0.0539 | I19: расчет | J19: m тигель+цеолит, г | K19: =K17+K18 -> 19.8597 | O19: расчет | P19: m тигель+GO, г | Q19: =Q17+Q18 -> 26.7851 | S19: #VALUE! | V19: m GO, г | W19: 0.0514 | AA19: взвешено | AB19: m тигель+GO, г | AD19: 32.5141 | AG19: взвешено | AH19: m тигель+GO, г | AJ19: 23.67 | AM19: расчет | AN19: m тигель+GO, г | AO19: 44.0688 | AS19: расчет | AT19: m тигель+GO, г | AU19: 23.2106 | AZ19: m тигель, г | BA19: 32.4621 | BE19: расчет | BF19: m тигель+GO, г | BG19: 30.9774 | BL19: Δр-Δэксп, г | BR19: Δр-Δэксп, г | BX19: Δр-Δэксп, г | CD19: Δр-Δэксп, г | CJ19: Δр-Δэксп, г | CP19: Δр-Δэксп, г | CU19: взвешено | CV19: m тигель+GO, г | CX19: 30.6303 | CY19: 1 | CZ19: 2 | DA19: 44.0625 | DB19: 0.0521 | DC19: 44.115 | DD19: 44.1303
C20: расчет | D20: m тигель+GO, г | E20: =E18+E19 -> 24.8207 | I20: взвешено | J20: m тигель+цеолит, г | K20: 19.8598 | L20: 19.8231 | M20: #VALUE! | O20: взвешено | P20: m тигель+GO, г | Q20: 26.7854 | R20: 26.7857 | U20: расчет | V20: m тигель+GO, г | W20: =W18+W19 -> 23.6517 | AB20: Δр-Δэксп, г | AH20: Δр-Δэксп, г | AM20: взвешено | AN20: m тигель+GO, г | AP20: 44.0715 | AS20: взвешено | AT20: m тигель+GO, г | AV20: 23.2185 | AZ20: m GO, г | BA20: 0.0519 | BE20: взвешено | BF20: m тигель+GO, г | BH20: 30.9946 | BL20: прирост массы | BN20: =BN18-BM17 -> 0.0054 | BR20: прирост массы | BT20: =BT18-BS17 -> 0.0075 | BX20: прирост массы | BZ20: =BZ18-BY17 -> 0.0248 | CD20: прирост массы | CF20: =CF18-CE17 -> 0.0043 | CJ20: прирост массы | CL20: =CL18-CK17 -> 0.0131 | CP20: прирост массы | CR20: =CR18-CQ17 -> 0.0044 | CV20: Δр-Δэксп, г | CY20: 1 | CZ20: 1 | DA20: 28.9499 | DB20: 0.0581 | DC20: 29.0082 | DD20: 29.0185
C21: взвешено | D21: m тигель+GO, г | E21: 24.8214 | F21: 24.8329 | J21: Δр-Δэксп, г | K21: =K19-K20 -> -0.0001 | P21: Δр-Δэксп, г | Q21: =Q19-Q20 -> -0.0003 | U21: взвешено | V21: m тигель+GO, г | W21: 23.6518 | X21: 23.6536 | AB21: прирост массы | AD21: =AD19-AC18 -> 0.003 | AH21: прирост массы | AJ21: =AJ19-AI18 -> 0.0469 | AN21: Δр-Δэксп, г | AT21: Δр-Δэксп, г | AY21: расчет | AZ21: m тигель+GO, г | BA21: 32.5143 | BF21: Δр-Δэксп, г | BL21: ω(probe в GO), % | BN21: =BN20/(BN20+BM16) -> 0.090301003 | BR21: ω(probe в GO), % | BT21: =BT20/(BT20+BS16) -> 0.12274959 | BX21: ω(probe в GO), % | BZ21: =BZ20/(BZ20+BY16) -> 0.32460733 | CD21: ω(probe в GO), % | CF21: =CF20/(CF20+CE16) -> 0.073005093 | CJ21: ω(probe в GO), % | CL21: =CL20/(CL20+CK16) -> 0.19494048 | CP21: ω(probe в GO), % | CR21: =CR20/(CR20+CQ16) -> 0.26829268 | CV21: прирост массы | CX21: =CX19-CW18 -> 0.0051 | CY21: 2 | CZ21: 1 | DA21: 30.4653 | DB21: 0.0555 | DC21: 30.8209 | DD21: 30.8408
D22: Δр-Δэксп, г | E22: =E20-E21 -> -0.0007 | J22: прирост массы | L22: =L20-K20 -> -0.0367 | P22: прирост массы | R22: =R20-Q20 -> 0.0003 | V22: Δр-Δэксп, г | W22: =W20-W21 -> -0.0001 | AB22: ω(морфолина в GO), % | AD22: =AD21/(AD21+AC17) -> 0.056710775 | AH22: ω(пирролидин в GO), % | AJ22: =AJ21/(AJ21+AI17) -> 0.46252465 | AN22: прирост массы | AP22: =AP20-AO19 -> 0.0027 | AT22: прирост массы | AV22: =AV20-AU19 -> 0.0079 | AY22: взвешено | AZ22: m тигель+GO, г | BB22: 32.5383 | BF22: прирост массы | BH22: =BH20-BG19 -> 0.0172 | BI22: Сорбция, ммоль/г | BL22: г/г | BM22: =BN20/BM16 -> 0.099264706 | BN22: =1000*(BN20/BJ14)/BM16 -> 1.2708322 | BO22: Сорбция, ммоль/г | BR22: г/г | BS22: =BT20/BS16 -> 0.13992537 | BT22: =1000*(BT20/BP14)/BS16 -> 4.1136736 | BU22: Сорбция, ммоль/г | BX22: г/г | BY22: =BZ20/BY16 -> 0.48062016 | BZ22: =1000*(BZ20/BV14)/BY16 -> 26.678887 | CA22: Сорбция, ммоль/г | CD22: г/г | CE22: =CF20/CE16 -> 0.078754579 | CF22: =1000*(CF20/CB14)/CE16 -> 0.98332599 | CG22: Сорбция, ммоль/г | CJ22: г/г | CK22: =CL20/CK16 -> 0.24214418 | CL22: =1000*(CL20/CH14)/CK16 -> 5.4945355 | CM22: Сорбция, ммоль/г | CP22: г/г | CQ22: =CR20/CQ16 -> 0.36666667 | CR22: =1000*(CR20/CN14)/CQ16 -> 4.6354239 | CV22: ω(probe в GO), % | CX22: =CX21/(CX21+CW17) -> 0.31097561
D23: прирост массы | F23: =F21-E21 -> 0.0115 | J23: ω(H2O в цеолите), % | L23: =L22/(L22+K18) -> -0.074156395 | P23: ω(Acac в GO), % | R23: =R22/(R22+Q18) -> 0.0057803468 | V23: прирост массы | X23: =X21-W21 -> 0.0018 | Y23: Сорбция, ммоль/г | AB23: г/г | AC23: =AD21/AC17 -> 0.06012024 | AD23: =1000*(AD21/Z15)/AC17 -> 0.33156434 | AE23: Сорбция, ммоль/г | AH23: г/г | AI23: =AJ21/AI17 -> 0.86055046 | AJ23: =1000*(AJ21/AF15)/AI17 -> 12.10168 | AN23: ω(Py в GO), % | AP23: =AP22/(AP22+AO18) -> 0.28125 | AT23: ω(probe в GO), % | AV23: =AV22/(AV22+AU18) -> 0.13504274 | AZ23: Δр-Δэксп, г | BF23: ω(probe в GO), % | BH23: =BH22/(BH22+BG18) -> 0.2236671 | BJ23: Rusgraphene 2 | BM23: 45887 | BN23: 45894 | BP23: Rusgraphene 2 | BS23: 45896 | BT23: 45903 | BV23: Rusgraphene 2 | BY23: 45897 | BZ23: 45904 | CB23: Rusgraphene 2 | CE23: 45897 | CF23: 45904 | CH23: Rusgraphene 2 | CK23: 45897 | CL23: 45904 | CN23: Rus2 GO | CQ23: 45917 | CR23: 45924 | CS23: Сорбция, ммоль/г | CV23: г/г | CW23: =CX21/CW17 -> 0.45132743 | CX23: =1000*(CX21/CT15)/CW17 -> 5.7057108 | CY23: CH3CN | CZ23: H2O | DA23: x(CH3CN) | DB23: г/г
D24: ω(AcOH в GO), % | F24: =F23/(F23+E19) -> 0.17584098 | M24: Сорбция, ммоль/г | P24: г/г | Q24: =R22/Q18 -> 0.0058139535 | R24: =1000*(R22/N16)/Q18 -> 0.058071591 | V24: ω(цитраконовый ангидрид в GO), % | X24: =X23/(X23+W19) -> 0.033834586 | AK24: Сорбция, ммоль/г | AN24: г/г | AO24: =AP22/AO18 -> 0.39130435 | AP24: =1000*(AP22/AL16)/AO18 -> 4.9469576 | AQ24: Сорбция, ммоль/г | AT24: г/г | AU24: =AV22/AU18 -> 0.15612648 | AV24: =1000*(AV22/AR16)/AU18 -> 0.56089988 | AZ24: прирост массы | BB24: =BB22-BA21 -> 0.024 | BC24: Сорбция, ммоль/г | BF24: г/г | BG24: =BH22/BG18 -> 0.2881072 | BH24: =1000*(BH22/BD16)/BG18 -> 3.2698582 | BI24: 45894 | BJ24: вода | BM24: 0.66666667 | BN24: 0.6875 | BO24: 45894 | BP24: Дейтеробензол (Бензол-D6) | BS24: 0.55555556 | BT24: 0.73958333 | BU24: 45904 | BV24: пиридин | BY24: 0.70833333 | BZ24: 0.6875 | CA24: 45904 | CB24: бензонитрил | CE24: 0.70833333 | CF24: 0.6875 | CG24: 45904 | CH24: CH3CN | CK24: 0.70833333 | CL24: 0.6875 | CM24: 45917 | CN24: пиридин | CQ24: 0.66666667 | CR24: 0.54166667 | CY24: 1 | CZ24: 0 | DA24: =1 -> 1 | DB24: =(DD17-DC17)/DB17 -> 0.30434783
A25: Сорбция, ммоль/г | D25: г/г | E25: =F23/E19 -> 0.21335807 | F25: =1000*(F23/B17)/E19 -> 3.5528887 | S25: Сорбция, ммоль/г | V25: г/г | W25: =X23/W19 -> 0.035019455 | X25: =1000*(X23/T17)/W19 -> 0.31245053 | Z25: Rusgraphene 2 | AC25: 45726 | AD25: 45733 | AF25: Rusgraphene 2 | AI25: 45733 | AJ25: 45741 | AZ25: ω(probe в GO), % | BB25: =BB24/(BB24+BA20) -> 0.31620553 | BD25: Rusgraphene 2 | BG25: 45862 | BH25: 45869 | BJ25: 18.015 | BK25: г/моль | BL25: Время, ч | BM25: 0 | BN25: 168 | BP25: 84.1488 | BQ25: г/моль | BR25: Время, ч | BS25: 0 | BT25: 168 | BV25: 79.101 | BW25: г/моль | BX25: Время, ч | BY25: 0 | BZ25: 168 | CB25: 103.04 | CC25: г/моль | CD25: Время, ч | CE25: 0 | CF25: 168 | CH25: 41.05 | CI25: г/моль | CJ25: Время, ч | CK25: 0 | CL25: 168 | CN25: 79.101 | CO25: г/моль | CP25: Время, ч | CQ25: 0 | CR25: 168 | CT25: Go rus2 5 um | CW25: 45917 | CX25: 45924 | CY25: 0 | CZ25: 1 | DA25: 0 | DB25: =(DD18-DC18)/DB18 -> 0.54301075
Q26: 45692 | R26: 45699 | Y26: 10/03/25-17/03/2025 | Z26: Лимонен -D, (-R) | AC26: 0.36111111 | AE26: 17.03.2025-24.03.2025 | AF26: пиперидин | AI26: 0.68055556 | AJ26: 0.45138889 | AL26: Rusgraphene 2 | AO26: 45817 | AP26: 45824 | AR26: Rusgraphene 2 | AU26: 45841 | AV26: 45848 | AW26: Сорбция, ммоль/г | AZ26: г/г | BA26: =BB24/BA20 -> 0.46242775 | BB26: =1000*(BB24/AX18)/BA20 -> 5.9186963 | BC26: 45869 | BD26: Et3N | BG26: 0.58333333 | BH26: 0.60416667 | BL26: m тигель, г | BM26: 32.4617 | BR26: m тигель, г | BS26: 29.0822 | BX26: m тигель, г | BY26: 29.0109 | CD26: m тигель, г | CE26: 31.3102 | CJ26: m тигель, г | CK26: 30.6138 | CP26: m тигель, г | CQ26: 32.9467 | CS26: 45917 | CT26: пиридин | CW26: 0.66666667 | CX26: 0.54166667 | CY26: 1 | CZ26: 2 | DA26: =1/3 -> 0.33333333 | DB26: =(DD19-DC19)/DB19 -> 0.29366603
E27: 45681 | F27: 45688 | M27: 04/02-11/02/25 | N27: ТБФ | Q27: 0.43402778 | R27: 0.54166667 | W27: 45699 | X27: 45706 | Z27: 136.24 | AA27: г/моль | AB27: Время, ч | AC27: 0 | AF27: 85.15 | AG27: г/моль | AH27: Время, ч | AI27: 0 | AJ27: 168 | AK27: 45817 | AL27: монометиланилин | AO27: 0.69444444 | AP27: 0.72916667 | AQ27: 45848 | AR27: n-Bu-NH2 | AU27: 0.58333333 | AV27: 0.60416667 | BD27: 101.191 | BE27: г/моль | BF27: Время, ч | BG27: 0 | BH27: 168 | BL27: m GO, г | BM27: 0.0519 | BR27: m GO, г | BS27: 0.0511 | BX27: m GO, г | BY27: 0.055 | CD27: m GO, г | CE27: 0.0518 | CJ27: m GO, г | CK27: 0.0531 | CP27: m GO, г | CQ27: 0.0574 | CT27: 79.101 | CU27: г/моль | CV27: Время, ч | CW27: 0 | CX27: 168 | CY27: 1 | CZ27: 1 | DA27: =1/2 -> 0.5 | DB27: =(DD20-DC20)/DB20 -> 0.17728055
A28: 23-31/01/25 | B28: SOCl2 | E28: 0.55208333 | F28: 0.45833333 | N28: 266.32 | O28: г/моль | P28: Время, ч | Q28: 0 | S28: 11/02/25-18/02/25 | T28: Цитраконовый ангидрид | W28: 0.66666667 | X28: 0.73611111 | Y28: #VALUE! | AB28: m тигель, г | AE28: #VALUE! | AH28: m тигель, г | AL28: 107.156 | AM28: г/моль | AN28: Время, ч | AO28: 0 | AP28: 168 | AR28: 73.139 | AS28: г/моль | AT28: Время, ч | AU28: 0 | AV28: 168 | AX28: Rusgraphene 2 | BA28: 45841 | BB28: 45848 | BF28: m тигель, г | BG28: 30.6804 | BK28: расчет | BL28: m тигель+GO, г | BM28: 32.5141 | BQ28: расчет | BR28: m тигель+GO, г | BS28: 29.1337 | BW28: расчет | BX28: m тигель+GO, г | BY28: 29.0662 | CC28: расчет | CD28: m тигель+GO, г | CE28: 31.3621 | CI28: расчет | CJ28: m тигель+GO, г | CK28: 30.6676 | CO28: расчет | CP28: m тигель+GO, г | CQ28: 33.0046 | CV28: m тигель, г | CW28: 30.39179 | CY28: 2 | CZ28: 1 | DA28: =2/3 -> 0.66666667 | DB28: =(DD21-DC21)/DB21 -> 0.35855856
B29: 118.97 | C29: г/моль | D29: Время, ч | E29: 0 | F29: 166 | P29: m тигель, г | Q29: 24.7661 | T29: 112.08 | U29: г/моль | V29: Время, ч | W29: 0 | X29: 170 | AB29: m GO, г | AC29: 0.0514 | AH29: m GO, г | AI29: 0.0546 | AN29: m тигель, г | AO29: 23.7635 | AT29: m тигель, г | AU29: 23.9914 | AW29: 45848 | AX29: DMF (ДМФА) | BA29: 0.58333333 | BB29: 0.60416667 | BF29: m GO, г | BG29: 0.0524 | BK29: взвешено | BL29: m тигель+GO, г | BN29: 32.5302 | BQ29: взвешено | BR29: m тигель+GO, г | BT29: 29.1397 | BW29: взвешено | BX29: m тигель+GO, г | BZ29: 29.0965 | CC29: взвешено | CD29: m тигель+GO, г | CF29: 31.3686 | CI29: взвешено | CJ29: m тигель+GO, г | CL29: 30.6761 | CO29: взвешено | CP29: m тигель+GO, г | CR29: 33.0412 | CV29: m GO, г | CW29: 0.00408
A30: #VALUE! | D30: m тигель, г | E30: 23.7632 | P30: m GO, г | Q30: 0.0535 | V30: m тигель, г | W30: 24.6225 | AA30: расчет | AB30: m тигель+GO, г | AC30: 29.2045 | AG30: расчет | AH30: m тигель+GO, г | AI30: 23.2148 | AN30: m GO, г | AO30: 0.0526 | AT30: m GO, г | AU30: 0.0533 | AX30: 73.09 | AY30: г/моль | AZ30: Время, ч | BA30: 0 | BB30: 168 | BE30: расчет | BF30: m тигель+GO, г | BG30: 30.7332 | BL30: Δр-Δэксп, г | BR30: Δр-Δэксп, г | BX30: Δр-Δэксп, г | CD30: Δр-Δэксп, г | CJ30: Δр-Δэксп, г | CP30: Δр-Δэксп, г | CU30: расчет | CV30: m тигель+GO, г | CW30: 30.39576
D31: m GO, г | E31: 0.0535 | O31: расчет | P31: m тигель+GO, г | Q31: =Q29+Q30 -> 24.8196 | S31: #VALUE! | V31: m GO, г | W31: 0.0525 | AA31: взвешено | AB31: m тигель+GO, г | AD31: 29.2102 | AG31: взвешено | AH31: m тигель+GO, г | AJ31: 23.246 | AM31: расчет | AN31: m тигель+GO, г | AO31: 23.8163 | AS31: расчет | AT31: m тигель+GO, г | AU31: 24.0452 | AZ31: m тигель, г | BA31: 29.0828 | BE31: взвешено | BF31: m тигель+GO, г | BH31: 30.7437 | BL31: прирост массы | BN31: =BN29-BM28 -> 0.0161 | BR31: прирост массы | BT31: =BT29-BS28 -> 0.006 | BX31: прирост массы | BZ31: =BZ29-BY28 -> 0.0303 | CD31: прирост массы | CF31: =CF29-CE28 -> 0.0065 | CJ31: прирост массы | CL31: =CL29-CK28 -> 0.0085 | CP31: прирост массы | CR31: =CR29-CQ28 -> 0.0366 | CU31: взвешено | CV31: m тигель+GO, г | CX31: 30.3998
C32: расчет | D32: m тигель+GO, г | E32: =E30+E31 -> 23.8167 | M32: #VALUE! | O32: взвешено | P32: m тигель+GO, г | Q32: 24.8202 | R32: 24.8215 | U32: расчет | V32: m тигель+GO, г | W32: =W30+W31 -> 24.675 | AB32: Δр-Δэксп, г | AH32: Δр-Δэксп, г | AM32: взвешено | AN32: m тигель+GO, г | AP32: 23.8245 | AS32: взвешено | AT32: m тигель+GO, г | AV32: 24.0913 | AZ32: m GO, г | BA32: 0.0527 | BF32: Δр-Δэксп, г | BL32: ω(probe в GO), % | BN32: =BN31/(BN31+BM27) -> 0.23676471 | BR32: ω(probe в GO), % | BT32: =BT31/(BT31+BS27) -> 0.10507881 | BX32: ω(probe в GO), % | BZ32: =BZ31/(BZ31+BY27) -> 0.35521688 | CD32: ω(probe в GO), % | CF32: =CF31/(CF31+CE27) -> 0.11149228 | CJ32: ω(probe в GO), % | CL32: =CL31/(CL31+CK27) -> 0.13798701 | CP32: ω(probe в GO), % | CR32: =CR31/(CR31+CQ27) -> 0.3893617 | CV32: Δр-Δэксп, г
C33: взвешено | D33: m тигель+GO, г | E33: 23.8166 | F33: 23.8207 | P33: Δр-Δэксп, г | Q33: =Q31-Q32 -> -0.0006 | U33: взвешено | V33: m тигель+GO, г | W33: 24.6752 | X33: 24.6784 | AB33: прирост массы | AD33: =AD31-AC30 -> 0.0057 | AH33: прирост массы | AJ33: =AJ31-AI30 -> 0.0312 | AN33: Δр-Δэксп, г | AT33: Δр-Δэксп, г | AY33: расчет | AZ33: m тигель+GO, г | BA33: 29.136 | BF33: прирост массы | BH33: =BH31-BG30 -> 0.0105 | BI33: Сорбция, ммоль/г | BL33: г/г | BM33: =BN31/BM27 -> 0.31021195 | BN33: =1000*(BN31/BJ25)/BM27 -> 17.219647 | BO33: Сорбция, ммоль/г | BR33: г/г | BS33: =BT31/BS27 -> 0.11741683 | BT33: =1000*(BT31/BP25)/BS27 -> 1.3953476 | BU33: Сорбция, ммоль/г | BX33: г/г | BY33: =BZ31/BY27 -> 0.55090909 | BZ33: =1000*(BZ31/BV25)/BY27 -> 6.9646287 | CA33: Сорбция, ммоль/г | CD33: г/г | CE33: =CF31/CE27 -> 0.12548263 | CF33: =1000*(CF31/CB25)/CE27 -> 1.217805 | CG33: Сорбция, ммоль/г | CJ33: г/г | CK33: =CL31/CK27 -> 0.16007533 | CL33: =1000*(CL31/CH25)/CK27 -> 3.8995208 | CM33: Сорбция, ммоль/г | CP33: г/г | CQ33: =CR31/CQ27 -> 0.63763066 | CR33: =1000*(CR31/CN25)/CQ27 -> 8.0609684 | CV33: прирост массы | CX33: =CX31-CW30 -> 0.00404
D34: Δр-Δэксп, г | E34: =E32-E33 -> 0.0001 | P34: прирост массы | R34: =R32-Q32 -> 0.0013 | V34: Δр-Δэксп, г | W34: =W32-W33 -> -0.0002 | AB34: ω(лимонен в GO), % | AD34: =AD33/(AD33+AC29) -> 0.099824869 | AH34: ω(пиперидин в GO), % | AJ34: =AJ33/(AJ33+AI29) -> 0.36363636 | AN34: прирост массы | AP34: =AP32-AO31 -> 0.0082 | AT34: прирост массы | AV34: =AV32-AU31 -> 0.0461 | AY34: взвешено | AZ34: m тигель+GO, г | BB34: 29.156 | BF34: ω(probe в GO), % | BH34: =BH33/(BH33+BG29) -> 0.16693164 | CV34: ω(probe в GO), % | CX34: =CX33/(CX33+CW29) -> 0.49753695
D35: прирост массы | F35: =F33-E33 -> 0.0041 | P35: ω(ТБФ в GO), % | R35: =R34/(R34+Q30) -> 0.023722628 | V35: прирост массы | X35: =X33-W33 -> 0.0032 | Y35: Сорбция, ммоль/г | AB35: г/г | AC35: =AD33/AC29 -> 0.11089494 | AD35: =1000*(AD33/Z27)/AC29 -> 0.81396757 | AE35: Сорбция, ммоль/г | AH35: г/г | AI35: =AJ33/AI29 -> 0.57142857 | AJ35: =1000*(AJ33/AF27)/AI29 -> 6.7108464 | AN35: ω(зонда в GO), % | AP35: =AP34/(AP34+AO30) -> 0.13486842 | AT35: ω(probe в GO), % | AV35: =AV34/(AV34+AU30) -> 0.4637827 | AZ35: Δр-Δэксп, г | BC35: Сорбция, ммоль/г | BF35: г/г | BG35: =BH33/BG29 -> 0.20038168 | BH35: =1000*(BH33/BD27)/BG29 -> 1.9802322 | CS35: Сорбция, ммоль/г | CV35: г/г | CW35: =CX33/CW29 -> 0.99019608 | CX35: =1000*(CX33/CT27)/CW29 -> 12.518123
D36: ω(SOCl2 в GO), % | F36: =F35/(F35+E31) -> 0.071180556 | M36: Сорбция, ммоль/г | P36: г/г | Q36: =R34/Q30 -> 0.024299065 | R36: =1000*(R34/N28)/Q30 -> 0.091240107 | V36: ω(цитраконовый ангидрид в GO), % | X36: =X35/(X35+W31) -> 0.057450628 | AK36: Сорбция, ммоль/г | AN36: г/г | AO36: =AP34/AO30 -> 0.15589354 | AP36: =1000*(AP34/AL28)/AO30 -> 1.4548279 | AQ36: Сорбция, ммоль/г | AT36: г/г | AU36: =AV34/AU30 -> 0.86491557 | AV36: =1000*(AV34/AR28)/AU30 -> 11.825641 | AZ36: прирост массы | BB36: =BB34-BA33 -> 0.02
A37: Сорбция, ммоль/г | D37: г/г | E37: =F35/E31 -> 0.076635514 | F37: =1000*(F35/B29)/E31 -> 0.64415831 | S37: Сорбция, ммоль/г | V37: г/г | W37: =X35/W31 -> 0.060952381 | X37: =1000*(X35/T29)/W31 -> 0.54382924 | AZ37: ω(probe в GO), % | BB37: =BB36/(BB36+BA32) -> 0.27510316
AQ38: МАСЛО!!! ОЧЕНЬ МНОГО! | AW38: Сорбция, ммоль/г | AZ38: г/г | BA38: =BB36/BA32 -> 0.37950664 | BB38: =1000*(BB36/AX30)/BA32 -> 5.1923196

Sheet Все корреляции авг25
C1: Сорбция, ммоль/г | D1: ε | E1: Kamlet–Taft | H1: DN, kcal/mol | I1: boiling temp
E2: α (донор) | F2: β (акцептор) | G2: π* (поляризуемость)
B3: уксусный ангидрид | C3: ='FTIR probes'!F12 -> 2.3731651 | D3: 21 | E3: 0 | F3: 0.291 | G3: 0.71 | H3: 17 | I3: 139.8
B4: 1,4-диоксан | C4: ='FTIR probes'!R12 -> 5.391513 | D4: 2.2 | E4: 0 | F4: 0.373 | G4: 0.55 | H4: 14.8 | I4: 101.1
B5: ='FTIR probes'!N15 -> Ацетилацетон | C5: ='FTIR probes'!R24 -> 0.058071591 | D5: 23.1 | E5: 0.11 | F5: 0.58 | G5: 0.75 | H5: 12.7 | I5: 140
B6: ='FTIR probes'!N27 -> ТБФ | C6: ='FTIR probes'!R36 -> 0.091240107 | D6: 3.09 | E6: 0 | F6: 0.75 | G6: 0.69 | H6: 20 | I6: 289
B7: ='FTIR probes'!T3 -> Фурфурол | C7: ='FTIR probes'!X12 -> 1.4719764 | D7: 42 | E7: 0.58 | F7: 0.6 | G7: 0.75 | H7: 17.1 | I7: 162
B8: ='FTIR probes'!Z2 -> Морфолин | C8: ='FTIR probes'!AD11 -> 7.617659 | D8: 7.4 | E8: 0.6 | F8: 0.66 | G8: 0.64 | H8: 27.1 | I8: 128
B9: ='FTIR probes'!AF2 -> NMP | C9: ='FTIR probes'!AJ11 -> 4.790569 | D9: 33 | E9: 0 | F9: 0.77 | G9: 0.92 | H9: 27.3 | I9: 202
B10: ='FTIR probes'!AF14 -> пирролидин | C10: ='FTIR probes'!AJ23 -> 12.10168 | D10: 8.3 | E10: 0.16 | F10: 0.7 | G10: 0.39 | H10: 33 | I10: 87
B11: ='FTIR probes'!AF26 -> пиперидин | C11: ='FTIR probes'!AJ35 -> 6.7108464 | D11: 5.8 | E11: 0 | F11: 1.04 | G11: 0.3 | H11: 27.5 | I11: 106
B12: ='FTIR probes'!AL2 -> TEMED | C12: ='FTIR probes'!AP11 -> 1.7050869 | D12: 7.4 | E12: 0.54 | F12: 0.8 | G12: 0.87 | H12: 28.8 | I12: 156
B13: ='FTIR probes'!AL15 -> пиридин | C13: ='FTIR probes'!AP24 -> 4.9469576 | D13: 12.4 | E13: 0.26 | F13: 0.57 | G13: 0.77 | H13: 33.1 | I13: 115
B14: ='FTIR probes'!AL27 -> монометиланилин | C14: ='FTIR probes'!AP36 -> 1.4548279 | D14: 6.06 | E14: 0.17 | F14: 0.47 | G14: 0.82 | H14: 11.5 | I14: 200
B15: ='FTIR probes'!AR27 -> n-Bu-NH2 | C15: ='FTIR probes'!AV36 -> 11.825641 | D15: 5.4 | E15: 0.84 | F15: 0.76 | G15: 1 | H15: 16.9 | I15: 78
B16: ='FTIR probes'!AX17 -> DMSO | C16: ='FTIR probes'!BB26 -> 5.9186963 | D16: 46.68 | E16: 0 | F16: 0.69 | G16: 1 | H16: 29.8 | I16: 189
B17: ='FTIR probes'!AX29 -> DMF (ДМФА) | C17: ='FTIR probes'!BB38 -> 5.1923196 | D17: 37 | E17: 0 | F17: 0.69 | G17: 1.18 | H17: 26.6 | I17: 153
B18: ='FTIR probes'!BD2 -> ТГФ | C18: ='FTIR probes'!BH11 -> 4.7372494 | D18: 7.6 | E18: 0 | F18: 0.55 | G18: 1 | H18: 20 | I18: 66
B19: ='FTIR probes'!BD15 -> Этилацетат | C19: ='FTIR probes'!BH24 -> 3.2698582 | D19: 6.02 | E19: 0 | F19: 0.45 | G19: 0.55 | H19: 17.1 | I19: 77
B20: Et3N | C20: ='FTIR probes'!BH35 -> 1.9802322 | D20: 2.42 | E20: 0 | F20: 0.7 | G20: 0.37 | H20: 61 | I20: 89
B21: Вода | C21: 7.5 | D21: 80 | E21: 1.09 | F21: 0.18 | G21: 1 | H21: 18 | I21: 100

Sheet Epsilon
A1: Name | B1: Sorption, mmol/g | C1: ε | D1: α | E1: β | F1: π* | G1: DN | H1: Molar Masses, g/mol | I1: Sorption, g/g
A2: 1,4-Dioxane | B2: 5.391513 | C2: 2.2 | D2: 0 | E2: 0.373 | F2: 0.55 | G2: 14.3 | H2: 88.106 | I2: =(B2*H2)/1000 -> 0.47502464
A3: Acetic anhydride | B3: 2.3731651 | C3: 21 | D3: 0 | E3: 0.291 | F3: 0.71 | G3: 10.5 | H3: 102.089 | I3: =(B3*H3)/1000 -> 0.24227405
A4: Acetic acid | B4: 3.5528887 | C4: 6.2 | D4: 1.121 | E4: 0.451 | F4: 0.58 | G4: 20 | H4: 60.052 | I4: =(B4*H4)/1000 -> 0.21335807
A5: Thionyl chloride | B5: 0.64415831 | C5: 9.25 | D5: 0 | E5: 0 | F5: 0 | G5: 0.4 | H5: 118.959 | I5: =(B5*H5)/1000 -> 0.076628428
A6: Acetylacetone | B6: 0.058071591 | C6: 23.1 | D6: 0.11 | E6: 0.58 | F6: 0.75 | H6: 100.117 | I6: =(B6*H6)/1000 -> 0.0058139535
A7: Tri-n-butyl phosphate (TBP) | B7: 0.091240107 | C7: 3.09 | D7: 0 | E7: 0.75 | F7: 0.69 | G7: 23.7 | H7: 266.318 | I7: =(B7*H7)/1000 -> 0.024298883
A8: Furfural | B8: 1.4719764 | C8: 42 | D8: 0.58 | E8: 0.6 | F8: 0.75 | H8: 96.085 | I8: =(B8*H8)/1000 -> 0.14143485
A9: Citraconic anhydride | B9: 0.54382924 | C9: 40.3 | H9: 112.084 | I9: =(B9*H9)/1000 -> 0.060954556
A10: 1,4-Dioxane | B10: 4.1607782 | C10: 2.2 | D10: 0 | E10: 0.373 | F10: 0.55 | H10: 88.106 | I10: =(B10*H10)/1000 -> 0.36658953
A11: Acetonitrile-d3 | B11: 5.4945355 | C11: 37.5 | H11: 44.071 | I11: =(B11*H11)/1000 -> 0.24214967
A12: Acetonitrile | B12: 3.8992359 | C12: 21.01 | D12: 0.19 | E12: 0.4 | F12: 0.75 | G12: 14.1 | H12: 41.053 | I12: =(B12*H12)/1000 -> 0.16007533
A13: Dimethylformamide (DMF) | B13: 5.1923196 | C13: 37 | D13: 0 | E13: 0.69 | F13: 1.18 | G13: 26.6 | H13: 73.095 | I13: =(B13*H13)/1000 -> 0.3795326
A14: Dimethyl sulfoxide (DMSO) | B14: 5.9186963 | C14: 46.68 | D14: 0 | E14: 0.69 | F14: 1 | G14: 29.8 | H14: 78.129 | I14: =(B14*H14)/1000 -> 0.46242183
A15: Triethylamine (Et3N) | B15: 1.9802322 | C15: 2.42 | D15: 0 | E15: 0.7 | F15: 0.37 | G15: 61 | H15: 101.193 | I15: =(B15*H15)/1000 -> 0.20038564
A16: Triethylamine (Et3N) | B16: 1.0269843 | C16: 2.42 | D16: 0 | E16: 0.7 | F16: 0.37 | G16: 61 | H16: 101.193 | I16: =(B16*H16)/1000 -> 0.10392362
A17: n-Butylamine | B17: 11.825641 | C17: 5.4 | D17: 0.84 | E17: 0.76 | F17: 1 | G17: 42 | H17: 73.139 | I17: =(B17*H17)/1000 -> 0.86491557
A18: N-Methyl-2-pyrrolidone (NMP) | B18: 4.790569 | C18: 33 | D18: 0 | E18: 0.77 | F18: 0.92 | G18: 27.3 | H18: 99.133 | I18: =(B18*H18)/1000 -> 0.47490347
A19: Phosphorus tribromide | B19: 1.7819385 | C19: 3.9 | H19: 270.686 | I19: =(B19*H19)/1000 -> 0.48234581
A20: N,N,N',N'-Tetramethylethylenediamine (TEMED) | B20: 1.7050869 | C20: 7.4 | D20: 0.54 | E20: 0.8 | F20: 0.87 | H20: 116.208 | I20: =(B20*H20)/1000 -> 0.19814474
A21: Benzene | B21: 1.2708322 | C21: 2.2825 | D21: 0 | E21: 0.1 | F21: 0.59 | G21: 0.1 | H21: 78.114 | I21: =(B21*H21)/1000 -> 0.099269789
A22: Benzonitrile | B22: 1.217805 | C22: 25.9 | D22: 0 | E22: 0.41 | F22: 0.9 | G22: 11.9 | H22: 103.124 | I22: =(B22*H22)/1000 -> 0.12558492
A23: Water | B23: 17.219647 | C23: 80.1 | G23: 18 | H23: 18.015 | I23: =(B23*H23)/1000 -> 0.31021195
A24: Water | B24: 26.678887 | C24: 80.1 | H24: 18.015 | I24: =(B24*H24)/1000 -> 0.48062016
A25: Benzene-d6 (Deuterated benzene) | B25: 1.3953476 | C25: 2.28 | H25: 84.151 | I25: =(B25*H25)/1000 -> 0.1174199
A26: Dibutyl phthalate | B26: 0.56089988 | C26: 6.44 | D26: 0.07 | E26: 0.45 | F26: 1.03 | H26: 278.348 | I26: =(B26*H26)/1000 -> 0.15612536
A27: Dicyclohexylamine | B27: 0.33156434 | C27: 2.27 | H27: 181.323 | I27: =(B27*H27)/1000 -> 0.06012024
A28: Limonene, D (R) | B28: 0.81396757 | C28: 2.3 | D28: 0 | E28: 0 | F28: 0.54 | H28: 136.238 | I28: =(B28*H28)/1000 -> 0.11089331
A29: N-Methylaniline | B29: 1.4548279 | C29: 6.06 | D29: 0.17 | E29: 0.47 | F29: 0.82 | G29: 33 | H29: 107.156 | I29: =(B29*H29)/1000 -> 0.15589354
A30: Morpholine | B30: 7.617659 | C30: 7.4 | D30: 0.6 | E30: 0.66 | F30: 0.64 | H30: 87.122 | I30: =(B30*H30)/1000 -> 0.66366569
A31: Hydrogen peroxide | B31: 4.1136736 | C31: 74.6 | H31: 34.014 | I31: =(B31*H31)/1000 -> 0.13992249
A32: Pivalonitrile | B32: 1.2912242 | C32: 21.1 | H32: 83.134 | I32: =(B32*H32)/1000 -> 0.10734463
A33: Piperidine | B33: 6.7108464 | C33: 5.8 | D33: 0 | E33: 1.04 | F33: 0.3 | G33: 40 | H33: 85.15 | I33: =(B33*H33)/1000 -> 0.57142857
A34: Pyridazine | B34: 0.98332599 | C34: 4.22 | H34: 80.09 | I34: =(B34*H34)/1000 -> 0.078754579
A35: Pyridine | B35: 4.9469576 | C35: 12.4 | D35: 0.26 | E35: 0.57 | F35: 0.77 | G35: 33.1 | H35: 79.102 | I35: =(B35*H35)/1000 -> 0.39131424
A36: Pyridine | B36: 6.9646287 | C36: 12.4 | D36: 0.26 | E36: 0.57 | F36: 0.77 | G36: 33.1 | H36: 79.102 | I36: =(B36*H36)/1000 -> 0.55091606
A37: Pyridine-d5 | B37: 3.7524068 | C37: 12.4 | H37: 84.133 | I37: =(B37*H37)/1000 -> 0.31570124
A38: Pyrrolidine | B38: 12.10168 | C38: 8.3 | D38: 0.16 | E38: 0.7 | F38: 0.39 | H38: 71.123 | I38: =(B38*H38)/1000 -> 0.86070778
A39: Tetrahydrofuran (THF) | B39: 4.7372494 | C39: 7.6 | D39: 0 | E39: 0.55 | F39: 1 | G39: 20 | H39: 72.107 | I39: =(B39*H39)/1000 -> 0.34158884
A40: Heavy water (D2O) | B40: 20.739268 | C40: 78 | H40: 20.027 | I40: =(B40*H40)/1000 -> 0.41534532
...
